Workbook

Sheet Task Tracker
A1: Brookline Budget Reform — Project Task Tracker
A2: Update status directly in this sheet. Filter by Branch, Status, or Priority to focus your work session.
A3: Branch | B3: Workstream | C3: Task | D3: Status | E3: Priority | F3: Owner | G3: Due / Notes | H3: Dependency | I3: Output | J3: Last Updated
A4: B1 · Econ Dev | B4: Site inventory | C4: Pull Brookline commercial parcel data from Assessor's Office | D4: To Do | E4: High | G4: brooklinema.gov/assessor | H4: — | I4: Commercial parcel spreadsheet | J4: —
A5: B1 · Econ Dev | B5: Site inventory | C5: Apply RKG Fiscal Impact Model to top 10 development sites | D5: To Do | E5: High | G5: Need RKG model access from Planning Dept | H5: Parcel data first | I5: Revenue per site estimates | J5: —
A6: B1 · Econ Dev | B6: Site inventory | C6: Build prioritized 10-year development pipeline with timeline estimates | D6: To Do | E6: Medium | H6: Site estimates | I6: Pipeline doc | J6: —
A7: B1 · Econ Dev | B7: Zoning reform | C7: Map current FAR and height limits for top commercial corridors (Beacon St, Harvard St, Rt 9) | D7: To Do | E7: High | G7: Zoning By-Law + GIS maps | H7: — | I7: Zoning gap analysis | J7: —
A8: B1 · Econ Dev | B8: Zoning reform | C8: Research Cambridge/Somerville as-of-right zoning models and revenue outcomes | D8: To Do | E8: Medium | G8: Web research + DLS snapshots | H8: — | I8: Comparable zoning memo | J8: —
A9: B1 · Econ Dev | B9: Zoning reform | C9: Draft specific zoning changes needed to unlock top 5 stalled sites | D9: To Do | E9: Medium | H9: Zoning gap analysis | I9: Zoning reform proposal | J9: —
A10: B1 · Econ Dev | B10: PILOT program | C10: Obtain full list of tax-exempt properties from Assessor | D10: To Do | E10: High | G10: brooklinema.gov/assessor | H10: — | I10: Non-profit property list | J10: —
A11: B1 · Econ Dev | B11: PILOT program | C11: Estimate value of non-exempt use properties for top 20 non-profit holders | D11: To Do | E11: Medium | H11: Non-profit property list | I11: PILOT revenue estimate | J11: —
A12: B1 · Econ Dev | B12: PILOT program | C12: Research existing Brookline PILOT agreements (e.g. 2 Brookline Place, Newbury on Fisher Hill) | D12: To Do | E12: Medium | G12: Town Counsel / Assessor records | H12: — | I12: PILOT precedent memo | J12: —
A13: B1 · Econ Dev | B13: PILOT program | C13: Design structured PILOT program with incentives and consequences | D13: To Do | E13: Low | H13: Revenue estimate + precedents | I13: Draft PILOT policy | J13: —
A14: B1 · Econ Dev | B14: Asset monetization | C14: Audit municipal parking lots: capacity, current revenue, lease potential | D14: To Do | E14: Medium | G14: DPW + Parking Dept data | H14: — | I14: Parking revenue analysis | J14: —
A15: B1 · Econ Dev | B15: Asset monetization | C15: Research golf course revenue vs. comparable municipal courses | D15: To Do | E15: Low | G15: Recreation Dept financials | H15: — | I15: Golf course memo | J15: —
A16: B1 · Econ Dev | B16: Asset monetization | C16: Map school building off-hours capacity and current rental rates vs. market | D16: To Do | E16: Medium | G16: PSB facilities data + E&RSC appendix | H16: — | I16: Facilities rental gap analysis | J16: —
A17: B1 · Econ Dev | B17: OOD SpEd expansion | C17: Quantify current OOD SpEd program capacity and waitlist demand | D17: To Do | E17: High | G17: PSB FY27 budget + DESE tuition tables | H17: — | I17: OOD capacity memo | J17: —
A18: B1 · Econ Dev | B18: OOD SpEd expansion | C18: Model revenue from expanding Winthrop House, ALC, LAHB to external students | D18: To Do | E18: High | G18: PSB FY27 budget (published Feb 5, 2026) | H18: Capacity memo | I18: OOD revenue model | J18: —
A19: B1 · Econ Dev | B19: Governance | C19: Draft proposed org structure: SB econ dev lead + elevated planning division | D19: To Do | E19: Medium | G19: E&RSC recommendations as baseline | H19: — | I19: Governance proposal | J19: —
A20: B2 · Legislative | B20: METCO SpEd costs | C20: Pull DESE SY24 in-district SpEd per-pupil cost data for Brookline | D20: To Do | E20: High | G20: dese.mass.edu — public data | H20: — | I20: SpEd cost baseline | J20: —
A21: B2 · Legislative | B21: METCO SpEd costs | C21: Quantify non-resident SpEd enrollment breakdown (METCO vs Materials Fee) | D21: To Do | E21: High | G21: PSB enrollment data — partial in E&RSC appendix | H21: — | I21: Non-resident SpEd enrollment table | J21: —
A22: B2 · Legislative | B22: METCO SpEd costs | C22: Calculate total annual unreimbursed SpEd cost with confidence interval | D22: To Do | E22: High | H22: Cost baseline + enrollment table | I22: Core financial claim ($4M figure) | J22: —
A23: B2 · Legislative | B23: Coalition mapping | C23: Research METCO enrollment at Newton, Wellesley, Lexington + their SpEd burden | D23: To Do | E23: High | G23: DESE public data + district annual reports | H23: — | I23: Coalition data brief | J23: —
A24: B2 · Legislative | B24: Coalition mapping | C24: Identify CFO/Superintendent contacts at Newton, Wellesley, Lexington for outreach | D24: To Do | E24: Medium | G24: District websites | H24: Coalition data | I24: Contact list | J24: —
A25: B2 · Legislative | B25: Coalition mapping | C25: Estimate total statewide unreimbursed METCO SpEd cost across all receiving districts | D25: To Do | E25: Medium | G25: DESE METCO program data | H25: Coalition data | I25: Statewide impact figure | J25: —
A26: B2 · Legislative | B26: Legislative strategy | C26: Identify Brookline's current State House delegation (Rep + Senator) | D26: To Do | E26: High | G26: malegislature.gov | H26: — | I26: Delegation contact sheet | J26: —
A27: B2 · Legislative | B27: Legislative strategy | C27: Search for existing bills on METCO reimbursement, Prop 2½, Ch. 70 reform | D27: To Do | E27: High | G27: malegislature.gov + MMA legislative tracker | H27: — | I27: Existing bills memo | J27: —
A28: B2 · Legislative | B28: Legislative strategy | C28: Determine best legislative vehicle: Ed Reform amendment vs. budget line item vs. Home Rule | D28: To Do | E28: Medium | G28: Town Counsel consultation recommended | H28: Existing bills memo | I28: Legislative pathway recommendation | J28: —
A29: B2 · Legislative | B29: Chapter 70 reform | C29: Analyze Brookline's Chapter 70 aid vs. foundation budget — is Brookline underfunded? | D29: To Do | E29: Medium | G29: DESE Foundation Budget data (public) | H29: — | I29: Ch. 70 gap analysis | J29: —
A30: B2 · Legislative | B30: Chapter 70 reform | C30: Research MMA's Chapter 70 reform proposals and Brookline's historical position | D30: To Do | E30: Low | G30: mma.org research + MMA 'Weathering the Storm' report | H30: — | I30: Ch. 70 reform memo | J30: —
A31: B2 · Legislative | B31: New revenue tools | C31: Research MA transfer tax legislation status (Boston/Cambridge precedent) | D31: To Do | E31: Medium | G31: malegislature.gov + Boston City Council records | H31: — | I31: Transfer tax memo | J31: —
A32: B2 · Legislative | B32: New revenue tools | C32: Inventory Home Rule petition options available to Brookline for new revenue tools | D32: To Do | E32: Low | G32: MA GL Home Rule authority + Town Counsel | H32: — | I32: Home Rule options list | J32: —
A33: B3 · OPEB Pivot | B33: OPEB liability | C33: Extract key figures from GASB 74/75 actuarial report (in E&RSC appendix) | D33: To Do | E33: High | G33: Already in E&RSC appendix — June 30, 2024 data | H33: — | I33: OPEB liability baseline | J33: —
A34: B3 · OPEB Pivot | B34: OPEB liability | C34: Determine current annual required contribution (ARC) and unfunded liability total | D34: To Do | E34: High | G34: GASB 74/75 report + MA PERAC data | H34: Liability baseline | I34: OPEB funding requirement | J34: —
... A36: B3 · OPEB Pivot | B36: $40M scenarios | C36: Build Scenario A model: all $40M to OPEB starting FY31 | D36: To Do | E36: High | G36: E&RSC Long-Range Financial Plan as baseline | H36: OPEB projection | I36: Scenario A model | J36: —
A37: B3 · OPEB Pivot | B37: $40M scenarios | C37: Build Scenario B model: $25M OPEB / $15M structural relief split | D37: To Do | E37: High | H37: Scenario A model | I37: Scenario B model | J37: —
A38: B3 · OPEB Pivot | B38: $40M scenarios | C38: Build Scenario C model: dynamic allocation tied to deficit + econ dev revenue | D38: To Do | E38: Medium | H38: Scenarios A+B | I38: Scenario C model | J38: —
A39: B3 · OPEB Pivot | B39: $40M scenarios | C39: Build Scenario D model: healthcare reform first, then OPEB pivot from stronger position | D39: To Do | E39: Medium | H39: Healthcare analysis | I39: Scenario D model | J39: —
A40: B3 · OPEB Pivot | B40: Moody's sensitivity | C40: Map which Moody's scoring factors OPEB funding affects (from E&RSC appendix scorecard) | D40: To Do | E40: High | G40: Moody's scorecard already in E&RSC appendix | H40: — | I40: Moody's factor map | J40: —
A41: B3 · OPEB Pivot | B41: Moody's sensitivity | C41: Model rating impact under Scenarios A-D — identify downgrade threshold | D41: To Do | E41: High | G41: Requires financial advisor input ideally | H41: Moody's factor map + scenarios | I41: Rating sensitivity analysis | J41: —
...

Sheet Dashboard
A1: Project Dashboard
A2: Formulas pull live from Task Tracker sheet. Update statuses there and this refreshes automatically.
A4: Overall Progress
A5: Branch | B5: Total Tasks | C5: Done | D5: In Progress | E5: Blocked | F5: To Do | G5: % Complete
A6: Branch 1 — Economic Development | B6: =COUNTIF('Task Tracker'!A:A,"B1 · Econ Dev") -> 16 | C6: =COUNTIFS('Task Tracker'!A:A,"B1 · Econ Dev",'Task Tracker'!D:D,"Done") -> 0 | D6: =COUNTIFS('Task Tracker'!A:A,"B1 · Econ Dev",'Task Tracker'!D:D,"In Progress") -> 0 | E6: =COUNTIFS('Task Tracker'!A:A,"B1 · Econ Dev",'Task Tracker'!D:D,"Blocked") -> 0 | F6: =COUNTIFS('Task Tracker'!A:A,"B1 · Econ Dev",'Task Tracker'!D:D,"To Do") -> 16 | G6: =IF(B6>0,C6/B6,0) -> 0
A7: Branch 2 — Legislative Strategy | B7: =COUNTIF('Task Tracker'!A:A,"B2 · Legislative") -> 13 | C7: =COUNTIFS('Task Tracker'!A:A,"B2 · Legislative",'Task Tracker'!D:D,"Done") -> 0 | D7: =COUNTIFS('Task Tracker'!A:A,"B2 · Legislative",'Task Tracker'!D:D,"In Progress") -> 0 | E7: =COUNTIFS('Task Tracker'!A:A,"B2 · Legislative",'Task Tracker'!D:D,"Blocked") -> 0 | F7: =COUNTIFS('Task Tracker'!A:A,"B2 · Legislative",'Task Tracker'!D:D,"To Do") -> 13 | G7: =IF(B7>0,C7/B7,0) -> 0
A8: Branch 3 — OPEB Pivot | B8: =COUNTIF('Task Tracker'!A:A,"B3 · OPEB Pivot") -> 14 | C8: =COUNTIFS('Task Tracker'!A:A,"B3 · OPEB Pivot",'Task Tracker'!D:D,"Done") -> 0 | D8: =COUNTIFS('Task Tracker'!A:A,"B3 · OPEB Pivot",'Task Tracker'!D:D,"In Progress") -> 0 | E8: =COUNTIFS('Task Tracker'!A:A,"B3 · OPEB Pivot",'Task Tracker'!D:D,"Blocked") -> 0 | F8: =COUNTIFS('Task Tracker'!A:A,"B3 · OPEB Pivot",'Task Tracker'!D:D,"To Do") -> 14 | G8: =IF(B8>0,C8/B8,0) -> 0
A9: Synthesis & Delivery | B9: =COUNTIF('Task Tracker'!A:A,"Synthesis") -> 7 | C9: =COUNTIFS('Task Tracker'!A:A,"Synthesis",'Task Tracker'!D:D,"Done") -> 0 | D9: =COUNTIFS('Task Tracker'!A:A,"Synthesis",'Task Tracker'!D:D,"In Progress") -> 0 | E9: =COUNTIFS('Task Tracker'!A:A,"Synthesis",'Task Tracker'!D:D,"Blocked") -> 0 | F9: =COUNTIFS('Task Tracker'!A:A,"Synthesis",'Task Tracker'!D:D,"To Do") -> 7 | G9: =IF(B9>0,C9/B9,0) -> 0
A10: TOTAL | B10: =SUM(B6:B9) -> 50 | C10: =SUM(C6:C9) -> 0 | D10: =SUM(D6:D9) -> 0 | E10: =SUM(E6:E9) -> 0 | F10: =SUM(F6:F9) -> 50 | G10: =IF(B10>0,C10/B10,0) -> 0
A12: Priority Breakdown — All Open Tasks
A13: Priority | B13: Total | C13: Done | D13: Remaining
A14: High | B14: =COUNTIF('Task Tracker'!E:E,"High") -> 20 | C14: =COUNTIFS('Task Tracker'!E:E,"High",'Task Tracker'!D:D,"Done") -> 0 | D14: =B14-C14 -> 20
A15: Medium | B15: =COUNTIF('Task Tracker'!E:E,"Medium") -> 21 | C15: =COUNTIFS('Task Tracker'!E:E,"Medium",'Task Tracker'!D:D,"Done") -> 0 | D15: =B15-C15 -> 21
A16: Low | B16: =COUNTIF('Task Tracker'!E:E,"Low") -> 9 | C16: =COUNTIFS('Task Tracker'!E:E,"Low",'Task Tracker'!D:D,"Done") -> 0 | D16: =B16-C16 -> 9

Sheet How To Use
A1: How To Use This Tracker
A3: UPDATING TASKS
A4: Status options: | B4: To Do | In Progress | Done | Blocked
A5: Priority options: | B5: High | Medium | Low
A6: Owner: | B6: Enter your name or initials in the Owner column
A7: Last Updated: | B7: Type today's date when you change a row
A8: Due / Notes: | B8: Use this for deadlines, context, or where to find source data
A10: FILTERING
A11: Filter by Branch: | B11: Click the dropdown on column A to focus on B1, B2, B3, or Synthesis
A12: Filter by Status: | B12: Column D — show only 'To Do' or 'In Progress' to see what's active
A13: Filter by Priority: | B13: Column E — start each session by showing only 'High' priority tasks
A14: Clear filters: | B14: Data > Clear Filter, or click the filter icon and select All
A16: STATUS COLORS
A17: To Do | B17: Gray — not started yet
A18: In Progress | B18: Yellow — actively being worked on
A19: Done | B19: Green — complete
A20: Blocked | B20: Red — waiting on something external
A22: DASHBOARD
A23: Live counts: | B23: The Dashboard sheet pulls live COUNTIF formulas from Task Tracker
A24: Refresh: | B24: Dashboard updates automatically as you change statuses — no action needed
A26: ADDING NEW TASKS
A27: Add rows: | B27: Insert a new row anywhere in the Task Tracker and fill in all columns
A28: Branch values: | B28: Must match exactly: B1 · Econ Dev | B2 · Legislative | B3 · OPEB Pivot | Synthesis
A29: Status values: | B29: Must match exactly: To Do | In Progress | Done | Blocked
A30: Priority values: | B30: Must match exactly: High | Medium | Low
A32: WORKFLOW SUGGESTION
A33: Start of session: | B33: Filter Status = In Progress. See what you were working on.
A34: Research sprint: | B34: Filter Priority = High, Status = To Do. Pick your next task.
A35: End of session: | B35: Update statuses. Add notes in Due/Notes. Update Last Updated date.
